Traceback (most recent call last):
  File "/Users/caballero/opt/anaconda3/envs/teaching/lib/python3.10/site-packages/jupyter_cache/executors/utils.py", line 58, in single_nb_execution
    executenb(
  File "/Users/caballero/opt/anaconda3/envs/teaching/lib/python3.10/site-packages/nbclient/client.py", line 1305, in execute
    return NotebookClient(nb=nb, resources=resources, km=km, **kwargs).execute()
  File "/Users/caballero/opt/anaconda3/envs/teaching/lib/python3.10/site-packages/jupyter_core/utils/__init__.py", line 173, in wrapped
    return loop.run_until_complete(inner)
  File "/Users/caballero/opt/anaconda3/envs/teaching/lib/python3.10/asyncio/base_events.py", line 649, in run_until_complete
    return future.result()
  File "/Users/caballero/opt/anaconda3/envs/teaching/lib/python3.10/site-packages/nbclient/client.py", line 705, in async_execute
    await self.async_execute_cell(
  File "/Users/caballero/opt/anaconda3/envs/teaching/lib/python3.10/site-packages/nbclient/client.py", line 1058, in async_execute_cell
    await self._check_raise_for_error(cell, cell_index, exec_reply)
  File "/Users/caballero/opt/anaconda3/envs/teaching/lib/python3.10/site-packages/nbclient/client.py", line 914, in _check_raise_for_error
    raise CellExecutionError.from_cell_and_msg(cell, exec_reply_content)
nbclient.exceptions.CellExecutionError: An error occurred while executing the following cell:
------------------
!pip install playsound
from playsound import playsound
playsound('data/D_PowerChords_95_SP.wav')
------------------

----- stdout -----
Requirement already satisfied: playsound in /Users/caballero/opt/anaconda3/envs/teaching/lib/python3.10/site-packages (1.3.0)
------------------

[0;31m---------------------------------------------------------------------------[0m
[0;31mPlaysoundException[0m                        Traceback (most recent call last)
Cell [0;32mIn[9], line 3[0m
[1;32m      1[0m get_ipython()[38;5;241m.[39msystem([38;5;124m'[39m[38;5;124mpip install playsound[39m[38;5;124m'[39m)
[1;32m      2[0m [38;5;28;01mfrom[39;00m [38;5;21;01mplaysound[39;00m [38;5;28;01mimport[39;00m playsound
[0;32m----> 3[0m [43mplaysound[49m[43m([49m[38;5;124;43m'[39;49m[38;5;124;43mdata/D_PowerChords_95_SP.wav[39;49m[38;5;124;43m'[39;49m[43m)[49m

File [0;32m~/opt/anaconda3/envs/teaching/lib/python3.10/site-packages/playsound.py:140[0m, in [0;36m_playsoundOSX[0;34m(sound, block)[0m
[1;32m    138[0m         logger[38;5;241m.[39mdebug([38;5;124m'[39m[38;5;124mFailed to load sound, although url was good... [39m[38;5;124m'[39m [38;5;241m+[39m sound)
[1;32m    139[0m [38;5;28;01melse[39;00m:
[0;32m--> 140[0m     [38;5;28;01mraise[39;00m PlaysoundException([38;5;124m'[39m[38;5;124mCould not load sound with filename, although URL was good... [39m[38;5;124m'[39m [38;5;241m+[39m sound)
[1;32m    141[0m nssound[38;5;241m.[39mplay()
[1;32m    143[0m [38;5;28;01mif[39;00m block:

[0;31mPlaysoundException[0m: Could not load sound with filename, although URL was good... file:///Users/caballero/Repos/teaching/phy415fall23/content/3_waves/data/D_PowerChords_95_SP.wav

